out/backtests/day17_hour/parquet_export.csv
ts_ns,type,side,price,qty
1756195622348000000,book,B,110119.47,0.01423
1756195622448000000,book,B,110119.48,0.14151
1756195622448000000,book,B,110119.47,0.0
1756195622448000000,book,B,110119.46,0.0
1756195622548000000,book,B,110119.48,0.0
1756195622548000000,book,B,110119.46,0.14151
1756195622649000000,book,B,110119.49,0.01423
1756195622749000000,book,B,110119.5,0.14151
1756195622749000000,book,B,110119.46,0.0
1756195622949000000,book,B,110119.49,0.0
1756195622949000000,book,B,110119.32,0.0
1756195623049000000,book,B,110119.5,0.0
1756195623049000000,book,B,110119.46,0.14151
1756195623049000000,book,A,137936.03,0.00036
1756195623449000000,book,B,110119.47,0.01423
1756195623549000000,book,B,110119.48,0.14151
1756195623549000000,book,B,110119.46,0.0
1756195623649000000,book,B,110119.47,0.0
1756195623749000000,book,B,110119.48,0.0
1756195623749000000,book,B,110119.46,0.14151
1756195624350000000,book,B,110119.34,0.0
1756195624450000000,book,B,110119.47,0.0003
1756195624550000000,book,B,110119.48,0.05806
1756195624550000000,book,B,110119.45,0.0
1756195624550000000,book,B,110106.0,0.0
1756195624550000000,book,B,110102.0,0.12263
1756195624550000000,book,A,110508.0,0.12232
1756195624550000000,book,A,110508.02,0.0
1756195624650000000,book,B,110119.5,0.05806
1756195624650000000,book,B,110119.49,0.14151
1756195624650000000,book,B,110119.48,0.0
1756195624650000000,book,B,110119.46,0.0
1756195624650000000,book,B,110102.0,0.0
1756195624650000000,book,B,110097.0,0.12263
1756195624650000000,book,A,110507.98,0.12232
1756195624650000000,book,A,110507.99,0.68404
1756195624650000000,book,A,110508.0,0.0
1756195624650000000,book,A,110508.01,0.0
1756195624750000000,book,B,110119.52,0.05806
1756195624750000000,book,B,110119.51,0.14151
1756195624750000000,book,B,110119.5,0.0
1756195624750000000,book,B,110119.49,0.0
1756195624750000000,book,B,110110.85,0.0
1756195624750000000,book,B,110097.0,0.0
1756195624750000000,book,B,110092.0,0.12263
1756195624750000000,book,A,110507.96,0.12232
1756195624750000000,book,A,110507.97,0.68404
1756195624750000000,book,A,110507.98,0.0
1756195624750000000,book,A,110507.99,0.0
1756195624850000000,book,B,110119.53,0.14151
1756195624850000000,book,B,110119.51,0.0
1756195624850000000,book,B,110099.36,0.03614
1756195624850000000,book,A,110507.95,0.68404
1756195624850000000,book,A,110507.97,0.0
1756195624950000000,book,B,110119.37,0.0
1756195624950000000,book,A,110508.04,0.0
1756195625050000000,book,B,110119.54,0.08383
1756195625050000000,book,A,110507.94,0.01081
1756195625150000000,book,B,110119.55,0.14151
1756195625150000000,book,B,110119.53,0.0
1756195625150000000,book,A,110507.93,0.68404
1756195625150000000,book,A,110507.95,0.0
1756195625150000000,book,A,137936.03,0.00036
1756195625250000000,book,B,110119.56,0.05806
1756195625250000000,book,B,110119.52,0.0
1756195625250000000,book,A,110507.92,0.12232
1756195625250000000,book,A,110507.94,0.006
1756195625250000000,book,A,110507.96,0.0
1756195625350000000,book,B,110119.57,0.14151
1756195625350000000,book,B,110119.55,0.0
1756195625350000000,book,A,110507.91,0.68404
1756195625350000000,book,A,110507.92,0.12816
1756195625350000000,book,A,110507.93,0.0
1756195625350000000,book,A,110508.06,0.0
1756195625551000000,book,A,110507.92,0.12335
1756195625651000000,book,A,110507.9,0.00481
1756195625751000000,book,A,110507.89,0.68404
1756195625751000000,book,A,110507.9,0.0
1756195625751000000,book,A,110507.91,0.0
1756195625851000000,book,A,110507.88,0.00481
1756195625851000000,book,A,110507.89,0.0
1756195625851000000,book,A,110507.91,0.68404
1756195625951000000,book,A,110507.87,0.68404
1756195625951000000,book,A,110507.91,0.0
1756195626051000000,book,A,110507.88,0.0
1756195626151000000,book,A,110507.86,0.68885
1756195626151000000,book,A,110507.87,0.0
1756195626151000000,book,A,110507.91,0.0
1756195626952000000,book,A,137936.03,0.00045
1756195627452000000,book,A,137936.03,0.00045
1756195628152000000,book,A,137936.03,0.00036
1756195628953000000,book,B,110099.36,0.0
1756195629053000000,book,A,110507.86,0.68404
1756195629153000000,book,B,110119.54,0.0
1756195629153000000,book,A,110507.86,0.0
1756195629153000000,book,A,110507.91,0.68404
1756195629153000000,book,A,110507.94,0.0
1756195629253000000,book,B,110119.58,0.08383
1756195629253000000,book,A,110507.9,0.006
1756195629353000000,book,B,110119.59,0.14151
1756195629353000000,book,B,110119.57,0.0
1756195629353000000,book,B,110119.47,0.0
1756195629353000000,book,A,110507.89,0.68404
1756195629353000000,book,A,110507.91,0.0
1756195629453000000,book,B,110119.59,0.14181
1756195629453000000,book,B,110110.95,0.0213
1756195629654000000,book,B,110118.76,0.0
1756195629754000000,book,B,110118.78,0.0
1756195629854000000,book,A,110507.88,0.00103
1756195629854000000,book,A,110507.92,0.12232
1756195629954000000,book,A,110507.87,0.1001
1756195629954000000,book,A,110507.89,0.58394
1756195630654000000,book,B,110119.6,0.00843
1756195630654000000,book,B,110119.57,0.0068
1756195630754000000,book,B,110119.61,0.14151
1756195630754000000,book,B,110119.59,0.0003
1756195630854000000,book,B,110119.62,0.05806
1756195630854000000,book,B,110119.56,0.0
1756195630854000000,book,B,110104.0,0.12263
1756195630854000000,book,B,110092.0,0.0
1756195630854000000,book,A,110507.86,0.12232
1756195630854000000,book,A,110507.92,0.0
1756195630954000000,book,B,110119.63,0.15343
1756195630954000000,book,B,110119.61,0.0
1756195630954000000,book,A,110507.85,0.68404
1756195630954000000,book,A,110507.87,0.0
1756195630954000000,book,A,110507.89,0.0
1756195631355000000,book,A,137936.03,0.00027
1756195631455000000,book,A,110507.84,0.0
1756195632055000000,book,A,110507.84,0.00312
1756195632155000000,book,A,110507.83,0.68404
1756195632155000000,book,A,110507.85,0.0
1756195632255000000,book,A,110507.84,0.0
1756195632355000000,book,A,110507.82,0.68404
1756195632355000000,book,A,110507.83,0.0
1756195632355000000,book,A,110507.85,0.0
1756195632455000000,book,A,110507.82,0.0
1756195632455000000,book,A,110507.85,0.68404
1756195632856000000,book,A,137936.03,0.00018
1756195633256000000,book,B,110119.58,0.0
1756195633256000000,book,A,110507.9,0.0
1756195633356000000,book,B,110119.64,0.08383
1756195633356000000,book,A,110507.85,0.69004
1756195633456000000,book,B,110119.65,0.14151
1756195633456000000,book,B,110119.63,0.01192
1756195633556000000,book,B,110119.66,0.01423
1756195633556000000,book,B,110119.63,0.0
1756195633656000000,book,B,110119.67,0.14151
1756195633656000000,book,B,110119.65,0.0
1756195633756000000,book,B,110119.66,0.0
1756195633856000000,book,B,110119.67,0.0
1756195633856000000,book,B,110119.65,0.14151
1756195634057000000,book,B,110119.66,0.01423
1756195634157000000,book,B,110119.67,0.14151
1756195634157000000,book,B,110119.65,0.0
1756195634257000000,book,B,110119.66,0.0
1756195634357000000,book,B,110119.68,0.01423
1756195634357000000,book,B,110119.67,0.0
1756195634357000000,book,B,110119.65,0.14151
1756195634457000000,book,B,110119.69,0.14151
1756195634457000000,book,B,110119.68,0.0
1756195634457000000,book,B,110119.65,0.0
1756195634557000000,book,B,110119.69,0.0
1756195634557000000,book,B,110119.65,0.14151
1756195634657000000,book,B,110119.7,0.01423
1756195634657000000,book,A,137936.03,0.00018
1756195634757000000,book,B,110119.71,0.14151
1756195634757000000,book,B,110119.65,0.0
1756195634957000000,book,B,110119.72,0.01423
1756195634957000000,book,B,110119.7,0.0
1756195635057000000,book,B,110119.73,0.14151
1756195635057000000,book,B,110119.71,0.0
1756195635157000000,book,B,110119.72,0.0
1756195635257000000,book,B,110119.74,0.01423
1756195635257000000,book,B,110119.73,0.0
1756195635257000000,book,B,110119.65,0.14151
1756195635357000000,book,B,110119.75,0.14151
1756195635357000000,book,B,110119.74,0.0
1756195635357000000,book,B,110119.65,0.0
1756195635357000000,book,A,137936.03,9e-05
1756195635458000000,book,B,110119.75,0.0
1756195635458000000,book,B,110119.65,0.14151
1756195635558000000,book,B,110119.76,0.01423
1756195635658000000,book,B,110119.77,0.14151
1756195635658000000,book,B,110119.65,0.0
1756195635858000000,book,B,110119.76,0.0
